Traceback (most recent call last):
  File "/Users/itam/miniconda3/lib/python3.12/site-packages/jupyter_cache/executors/utils.py", line 58, in single_nb_execution
    executenb(
  File "/Users/itam/miniconda3/lib/python3.12/site-packages/nbclient/client.py", line 1319, in execute
    return NotebookClient(nb=nb, resources=resources, km=km, **kwargs).execute()
           ^^^^^^^^^^^^^^^^^^^^^^^^^^^^^^^^^^^^^^^^^^^^^^^^^^^^^^^^^^^^^^^^^^^^^
  File "/Users/itam/miniconda3/lib/python3.12/site-packages/jupyter_core/utils/__init__.py", line 165, in wrapped
    return loop.run_until_complete(inner)
           ^^^^^^^^^^^^^^^^^^^^^^^^^^^^^^
  File "/Users/itam/miniconda3/lib/python3.12/asyncio/base_events.py", line 685, in run_until_complete
    return future.result()
           ^^^^^^^^^^^^^^^
  File "/Users/itam/miniconda3/lib/python3.12/site-packages/nbclient/client.py", line 709, in async_execute
    await self.async_execute_cell(
  File "/Users/itam/miniconda3/lib/python3.12/site-packages/nbclient/client.py", line 1062, in async_execute_cell
    await self._check_raise_for_error(cell, cell_index, exec_reply)
  File "/Users/itam/miniconda3/lib/python3.12/site-packages/nbclient/client.py", line 918, in _check_raise_for_error
    raise CellExecutionError.from_cell_and_msg(cell, exec_reply_content)
nbclient.exceptions.CellExecutionError: An error occurred while executing the following cell:
------------------
# Question 1
plus_thirteen = []
for ______ in range(1,11):
  plus_thirteen._______(________)
print(plus_thirteen)
------------------


[0;31m---------------------------------------------------------------------------[0m
[0;31mAttributeError[0m                            Traceback (most recent call last)
Cell [0;32mIn[1], line 4[0m
[1;32m      2[0m plus_thirteen [38;5;241m=[39m []
[1;32m      3[0m [38;5;28;01mfor[39;00m ______ [38;5;129;01min[39;00m [38;5;28mrange[39m([38;5;241m1[39m,[38;5;241m11[39m):
[0;32m----> 4[0m   [43mplus_thirteen[49m[38;5;241;43m.[39;49m[43m_______[49m(________)
[1;32m      5[0m [38;5;28mprint[39m(plus_thirteen)

[0;31mAttributeError[0m: 'list' object has no attribute '_______'

